{
  try {
    start();
    init();
    init();
  }
 catch (  Exception e) {
    assertTrue("Exception was caught during testInit test: " + e.getMessage(),false);
  }
}
